<?xml version="1.0"?>
<robot xmlns:xacro="http://ros.org/wiki/xacro">
  <xacro:macro name="khi_rs005l" params="prefix">

    <xacro:include filename="$(find mobile_manipulator_description)/urdf/khi_rs/rs.transmission.xacro" />
    <xacro:include filename="$(find mobile_manipulator_description)/urdf/khi_rs/common.gazebo.xacro" />

    <!-- link rviz colors -->
    <material name="White">
      <color rgba="1 1 1 1"/>
    </material>

    <material name="Black">
      <color rgba="0 0 0 1"/>
    </material>

    <!-- DH parameters -->
    <xacro:property name="dh_j1_j2_roty" value="${radians(90)}"/>
    <xacro:property name="dh_j3_j4_roty" value="${radians(90)}"/>
    <xacro:property name="dh_j4_j5_roty" value="${radians(90)}"/>
    <xacro:property name="dh_j5_j6_roty" value="${radians(90)}"/>

    <!-- link mass [kg] -->
    <xacro:property name="j0_mass" value="5.910"/>
    <xacro:property name="j1_mass" value="10.395"/>
    <xacro:property name="j2_mass" value="8.788"/>
    <xacro:property name="j3_mass" value="7.575"/>
    <xacro:property name="j4_mass" value="2.679"/>
    <xacro:property name="j5_mass" value="1.028"/>
    <xacro:property name="j6_mass" value="0.625"/>

    <!-- link lengths [m] -->
    <xacro:property name="j0_length" value="0.295"/>
    <xacro:property name="j1_length" value="0.105"/>
    <xacro:property name="j2_length" value="0.380"/>
    <xacro:property name="j31_length" value="0.15"/>
    <xacro:property name="j32_length" value="0.080"/>
    <xacro:property name="j4_length" value="0.410"/>
    <xacro:property name="j5_length" value="0.078"/>
    
    <!-- joint limits [rad] -->
    <xacro:property name="j1_lower_limit" value="${radians(-180)}"/>
    <xacro:property name="j1_upper_limit" value="${radians( 180)}"/>
    <xacro:property name="j2_lower_limit" value="${radians( -80)}"/>
    <xacro:property name="j2_upper_limit" value="${radians( 135)}"/>
    <xacro:property name="j3_lower_limit" value="${radians(-172)}"/>
    <xacro:property name="j3_upper_limit" value="${radians( 118)}"/>
    <xacro:property name="j4_lower_limit" value="${radians(-360)}"/>
    <xacro:property name="j4_upper_limit" value="${radians( 360)}"/>
    <xacro:property name="j5_lower_limit" value="${radians(-145)}"/>
    <xacro:property name="j5_upper_limit" value="${radians( 145)}"/>
    <xacro:property name="j6_lower_limit" value="${radians(-360)}"/>
    <xacro:property name="j6_upper_limit" value="${radians( 360)}"/>

    <!-- joint verocity limits [rad/s] -->
    <xacro:property name="j1_velocity_limit" value="${radians( 300)}"/>
    <xacro:property name="j2_velocity_limit" value="${radians( 300)}"/>
    <xacro:property name="j3_velocity_limit" value="${radians( 300)}"/>
    <xacro:property name="j4_velocity_limit" value="${radians( 460)}"/>
    <xacro:property name="j5_velocity_limit" value="${radians( 460)}"/>
    <xacro:property name="j6_velocity_limit" value="${radians( 740)}"/>

    <!-- link inertial(TODO : set correct link inertial )-->
    <xacro:macro name="default_inertial" params="mass">
      <inertial>
        <mass value="${mass}" />
        <inertia ixx="1.0" ixy="0.0" ixz="0.0" iyy="1.0" iyz="0.0" izz="1.0" />
      </inertial>
    </xacro:macro>

    <!-- rs007l start -->

    <!-- Link 0 -->
    <link name="${prefix}base_link">
      <visual>
        <geometry>
          <mesh filename="package://mobile_manipulator_description/meshes/khi_rs/RS005L_J0.STL"/>
        </geometry>
        <material name="White"/>
        <origin rpy="0 0 0" xyz="0 0 0"/>
      </visual>
      <collision>
        <geometry>
          <mesh filename="package://mobile_manipulator_description/meshes/khi_rs/RS005L_J0.STL"/>
        </geometry>
        <material name="White"/>
        <origin rpy="0 0 0" xyz="0 0 0"/>
      </collision>
      <xacro:default_inertial mass="${j0_mass}"/>
    </link>

    <!-- Link 1 -->
    <joint name="${prefix}joint1" type="revolute">
      <axis xyz="0 0 -1" rpy="0 0 0" />
      <limit effort="1000.0" lower="${j1_lower_limit}" upper="${j1_upper_limit}" velocity="${j1_velocity_limit}"/>
      <origin xyz="0 0 ${j0_length}" rpy="0 0 0" />
      <parent link="${prefix}base_link"/>
      <child link="${prefix}link1"/>
      <dynamics damping="0.0" friction="0.0"/>
    </joint>


    <link name="${prefix}link1">
      <visual>
        <geometry>
          <mesh filename="package://mobile_manipulator_description/meshes/khi_rs/RS005L_J1.STL"/>
        </geometry>
        <material name="White"/>
        <origin rpy="0 0 0" xyz="0 0 0"/>
      </visual>
      <collision>
        <geometry>
          <mesh filename="package://mobile_manipulator_description/meshes/khi_rs/RS005L_J1.STL"/>
        </geometry>
        <material name="White"/>
        <origin rpy="0 0 0" xyz="0 0 0"/>
      </collision>
      <xacro:default_inertial mass="${j1_mass}"/>
    </link>

    <!-- Link 2 -->
    <joint name="${prefix}joint2" type="revolute">
      <axis xyz="0 0 1" rpy="0 0 0" />
      <limit effort="1000.0" lower="${j2_lower_limit}" upper="${j2_upper_limit}" velocity="${j2_velocity_limit}"/>
      <origin xyz="0 ${j1_length} 0" rpy="0 ${dh_j1_j2_roty*-1} 0" />
      <parent link="${prefix}link1"/>
      <child link="${prefix}link2"/>
      <dynamics damping="0.0" friction="0.0"/>
    </joint>

    <link name="${prefix}link2">
      <visual>
        <geometry>
          <mesh filename="package://mobile_manipulator_description/meshes/khi_rs/RS005L_J2.STL"/>
        </geometry>
        <material name="White"/>
        <origin xyz="0 0 0" rpy="0 0 0"/>
      </visual>
      <collision>
        <geometry>
          <mesh filename="package://mobile_manipulator_description/meshes/khi_rs/RS005L_J2.STL"/>
        </geometry>
        <material name="White"/>
        <origin xyz="0 0 0" rpy="0 0 0"/>
      </collision>
      <xacro:default_inertial mass="0${j2_mass}"/>
    </link>

    <!-- Link 3 -->
    <joint name="${prefix}joint3" type="revolute">
      <axis xyz="0 0 -1" rpy="0 0 0" />
      <limit effort="1000.0" lower="${j3_lower_limit}" upper="${j3_upper_limit}" velocity="${j3_velocity_limit}"/>
      <origin xyz="${j2_length} 0 0" rpy="0 0 0" />
      <parent link="${prefix}link2"/>
      <child link="${prefix}link3"/>
      <dynamics damping="0.0" friction="0.0"/>
    </joint>

    <link name="${prefix}link3">
      <visual>
        <geometry>
          <mesh filename="package://mobile_manipulator_description/meshes/khi_rs/RS005L_J3.STL"/>
        </geometry>
        <material name="White"/>
        <origin xyz="0 0 0" rpy="0 0 0"/>
      </visual>
      <collision>
        <geometry>
          <mesh filename="package://mobile_manipulator_description/meshes/khi_rs/RS005L_J3.STL"/>
        </geometry>
        <material name="White"/>
        <origin xyz="0 0 0" rpy="0 0 0"/>
      </collision>
      <xacro:default_inertial mass="${j3_mass}"/>
    </link>

    <!-- Link 4 -->
    <joint name="${prefix}joint4" type="revolute">
      <axis xyz="0 0 1" rpy="0 0 0" />
      <limit effort="1000.0" lower="${j4_lower_limit}" upper="${j4_upper_limit}" velocity="${j4_velocity_limit}"/>
      <origin xyz="${j31_length} ${j32_length*-1} 0" rpy="0 ${dh_j3_j4_roty} 0" />
      <parent link="${prefix}link3"/>
      <child link="${prefix}link4"/>
      <dynamics damping="0.0" friction="0.0"/>
    </joint>

    <link name="${prefix}link4">
      <visual>
        <geometry>
          <mesh filename="package://mobile_manipulator_description/meshes/khi_rs/RS005L_J4.STL"/>
        </geometry>
        <material name="White"/>
        <origin xyz="0 0 0" rpy="0 0 0"/>
      </visual>
      <collision>
        <geometry>
          <mesh filename="package://mobile_manipulator_description/meshes/khi_rs/RS005L_J4.STL"/>
        </geometry>
        <material name="White"/>
        <origin xyz="0 0 0" rpy="0 0 0"/>
      </collision>
      <xacro:default_inertial mass="${j4_mass}"/>
    </link>

    <!-- Link 5 -->
    <joint name="${prefix}joint5" type="revolute">
      <axis xyz="0 0 -1" rpy="0 0 0" />
      <limit effort="1000.0" lower="${j5_lower_limit}" upper="${j5_upper_limit}" velocity="${j5_velocity_limit}"/>
      <origin xyz="0 0 0.26" rpy="0 ${dh_j4_j5_roty*-1} 0" />
      <parent link="${prefix}link4"/>
      <child link="${prefix}link5"/>
      <dynamics damping="0.0" friction="0.0"/>
    </joint>

    <link name="${prefix}link5">
      <visual>
        <geometry>
          <mesh filename="package://mobile_manipulator_description/meshes/khi_rs/RS005L_J5.STL"/>
        </geometry>
        <material name="White"/>
        <origin xyz="0 0 0" rpy="0 0 0"/>
      </visual>
      <collision>
        <geometry>
          <mesh filename="package://mobile_manipulator_description/meshes/khi_rs/RS005L_J5.STL"/>
        </geometry>
        <material name="White"/>
        <origin xyz="0 0 0" rpy="0 0 0"/>
      </collision>
      <xacro:default_inertial mass="${j5_mass}"/>
    </link>

    <!-- Link 6 -->
    <joint name="${prefix}joint6" type="revolute">
      <axis xyz="0 0 1" rpy="0 0 0" />
      <limit effort="1000.0" lower="${j6_lower_limit}" upper="${j6_upper_limit}" velocity="${j6_velocity_limit}"/>
      <origin xyz="${j5_length} 0 0" rpy="0 ${dh_j5_j6_roty} 0" />
      <parent link="${prefix}link5"/>
      <child link="${prefix}link6"/>
      <dynamics damping="0.0" friction="0.0"/>
    </joint>

    <link name="${prefix}link6">
      <visual>
        <geometry>
          <mesh filename="package://mobile_manipulator_description/meshes/khi_rs/RS005L_J6.STL"/>
        </geometry>
        <material name="Black"/>
        <origin xyz="0 0 0" rpy="0 0 0"/>
      </visual>
      <collision>
        <geometry>
          <mesh filename="package://mobile_manipulator_description/meshes/khi_rs/RS005L_J6.STL"/>
        </geometry>
        <material name="Black"/>
        <origin xyz="0 0 0" rpy="0 0 0"/>
      </collision>
      <xacro:default_inertial mass="${j6_mass}"/>
    </link>

    <!-- Link 7 -->
    <joint name="${prefix}joint7" type="fixed">
      <axis xyz="0 0 1" rpy="0 0 0" />
      <origin xyz="0 0 0" rpy="0 0 -1.96" />
      <parent link="${prefix}link6"/>
      <child link="${prefix}link7"/>
    </joint>


        <link name="${prefix}link7">
      <visual>
        <geometry>
          <mesh filename="package://mobile_manipulator_description/meshes/khi_rs/Montaj.stl" scale="0.001 0.001 0.001"/>
        </geometry>
        <material name="Black"/>
        <origin xyz="-0.035 -0.04 0.2175" rpy="1.570796 3.1415 0"/>
      </visual>
      <collision>
        <geometry>
          <mesh filename="package://mobile_manipulator_description/meshes/khi_rs/Montaj.stl" scale="0.001 0.001 0.001"/>
        </geometry>
        <material name="Black"/>
        <origin xyz="-0.035 -0.04 0.2175" rpy="1.570796 3.1415 0"/>
      </collision>
      <xacro:default_inertial mass="0.1"/>
    </link>
<!--
    <link name="camera_link"/>

    <joint name="camera_joint" type="fixed">
       <origin xyz="0.0145 0.0125 0.185" rpy="0 -1.570796 1.570796"/>
       <parent link="${prefix}link7"/>
       <child link="camera_link"/>
    </joint>
    <joint name="camera_rgb_joint" type="fixed">
       <origin xyz="0 0 0" rpy="0 0 0"/>
       <parent link="camera_link"/>
       <child link="camera_rgb_frame"/>
    </joint>
    <link name="camera_rgb_frame"/>

    <joint name="camera_rgb_optic_joint" type="fixed">
       <origin xyz="0 0 0" rpy="0 0 0"/>
       <parent link="camera_rgb_frame"/>
       <child link="camera_rgb_optic_frame"/>
    </joint>
     
    <link name="camera_rgb_optic_frame"/>

    <gazebo reference="camera_link">
      <sensor type="depth" name="Realsense_Camera_Depth">
      <always_on>true</always_on>
      <update_rate>10.0</update_rate>
      <camera>
        <horizontal_fov>1.22</horizontal_fov>
        <image>
          <width>512</width>
          <height>424</height>
          <format>R8G8B8</format>
        </image>
        <clip>
          <near>0.01</near>
          <far>16</far>
        </clip>
      </camera>
      <visualize>True</visualize>      
      <plugin name="depth_camera_plugin" filename="libgazebo_ros_openni_kinect.so">
        <alwaysOn>true</alwaysOn>
        <updateRate>10.0</updateRate>
        <cameraName>camera</cameraName>
        <imageTopicName>image_raw</imageTopicName>
        <cameraInfoTopicName>camera_info</cameraInfoTopicName>
        <depthImageTopicName>depth_image_raw</depthImageTopicName>
        <depthImageCameraInfoTopicName>depth_camera_info</depthImageCameraInfoTopicName>
        <pointCloudTopicName>points</pointCloudTopicName>
        <frameName>camera_rgb_optic_frame</frameName>
        <pointCloudCutoff>0.0</pointCloudCutoff>
        <distortionK1>0.00000001</distortionK1>
        <distortionK2>0.00000001</distortionK2>
        <distortionK3>0.00000001</distortionK3>
        <distortionT1>0.00000001</distortionT1>
        <distortionT2>0.00000001</distortionT2>
        <CxPrime>0</CxPrime>
        <Cx>0</Cx>
        <Cy>0</Cy>
        <focalLength>0</focalLength>
        <hackBaseline>0</hackBaseline>
      </plugin>    
      </sensor>
    </gazebo>-->
  </xacro:macro>
</robot>
