<?xml version="1.0" ?>
<!-- =================================================================================== -->
<!-- |    This document was autogenerated by xacro from /home/didem-focal/catkin_ws/src/mobile_manipulator/mobile_manipulator_description/urdf/mobile_manipulator.urdf.xacro | -->
<!-- |    EDITING THIS FILE BY HAND IS NOT RECOMMENDED                                 | -->
<!-- =================================================================================== -->
<robot name="robot">
    <property name="M_PI" value="3.1415926535897931" />
    <!-- see https://secure.wikimedia.org/wikipedia/en/wiki/List_of_moment_of_inertia_tensors -->
    <property name="M_PI" value="3.1415926535897931" />
    <transmission name="$join1_trans">
        <type>transmission_interface/SimpleTransmission</type>
        <actuator name="joint1_motor">
            <hardwareInterface>hardware_interface/PositionJointInterface</hardwareInterface>
            <mechanicalReduction>1</mechanicalReduction>
        </actuator>
        <joint name="joint1">
            <hardwareInterface>hardware_interface/PositionJointInterface</hardwareInterface>
        </joint>
    </transmission>
    <transmission name="$join2_trans">
        <type>transmission_interface/SimpleTransmission</type>
        <actuator name="joint2_motor">
            <hardwareInterface>hardware_interface/PositionJointInterface</hardwareInterface>
            <mechanicalReduction>1</mechanicalReduction>
        </actuator>
        <joint name="joint2">
            <hardwareInterface>hardware_interface/PositionJointInterface</hardwareInterface>
        </joint>
    </transmission>
    <transmission name="$join3_trans">
        <type>transmission_interface/SimpleTransmission</type>
        <actuator name="joint3_motor">
            <hardwareInterface>hardware_interface/PositionJointInterface</hardwareInterface>
            <mechanicalReduction>1</mechanicalReduction>
        </actuator>
        <joint name="joint3">
            <hardwareInterface>hardware_interface/PositionJointInterface</hardwareInterface>
        </joint>
    </transmission>
    <transmission name="$join4_trans">
        <type>transmission_interface/SimpleTransmission</type>
        <actuator name="joint4_motor">
            <hardwareInterface>hardware_interface/PositionJointInterface</hardwareInterface>
            <mechanicalReduction>1</mechanicalReduction>
        </actuator>
        <joint name="joint4">
            <hardwareInterface>hardware_interface/PositionJointInterface</hardwareInterface>
        </joint>
    </transmission>
    <transmission name="$join5_trans">
        <type>transmission_interface/SimpleTransmission</type>
        <actuator name="joint5_motor">
            <hardwareInterface>hardware_interface/PositionJointInterface</hardwareInterface>
            <mechanicalReduction>1</mechanicalReduction>
        </actuator>
        <joint name="joint5">
            <hardwareInterface>hardware_interface/PositionJointInterface</hardwareInterface>
        </joint>
    </transmission>
    <transmission name="$join6_trans">
        <type>transmission_interface/SimpleTransmission</type>
        <actuator name="joint6_motor">
            <hardwareInterface>hardware_interface/PositionJointInterface</hardwareInterface>
            <mechanicalReduction>1</mechanicalReduction>
        </actuator>
        <joint name="joint6">
            <hardwareInterface>hardware_interface/PositionJointInterface</hardwareInterface>
        </joint>
    </transmission>
    <!-- gazebo plugin -->
    <gazebo>
        <plugin filename="libgazebo_ros_control.so" name="gazebo_ros_control">
            <robotNamespace>/</robotNamespace>
            <robotSimType>gazebo_ros_control/DefaultRobotHWSim</robotSimType>
            <legacyModeNS>true</legacyModeNS>
        </plugin>
        <!--
    <plugin name="gazebo_ros_power_monitor_controller" filename="libgazebo_ros_power_monitor.so">
      <alwaysOn>true</alwaysOn>
      <updateRate>1.0</updateRate>
      <timeout>5</timeout>
      <powerStateTopic>power_state</powerStateTopic>
      <powerStateRate>10.0</powerStateRate>
      <fullChargeCapacity>87.78</fullChargeCapacity>     
      <dischargeRate>-474</dischargeRate>
      <chargeRate>525</chargeRate>
      <dischargeVoltage>15.52</dischargeVoltage>
      <chargeVoltage>16.41</chargeVoltage>
    </plugin>
-->
    </gazebo>
    <!-- link rviz colors -->
    <material name="White">
        <color rgba="1 1 1 1" />
    </material>
    <material name="Black">
        <color rgba="0 0 0 1" />
    </material>
    <!-- rs007l start -->
    <!-- Link 0 -->
    <link name="base_link">
        <visual>
            <geometry>
                <mesh filename="package://mobile_manipulator_description/meshes/khi_rs/RS005L_J0.STL" />
            </geometry>
            <material name="White" />
            <origin rpy="0 0 0" xyz="0 0 0" />
        </visual>
        <collision>
            <geometry>
                <mesh filename="package://mobile_manipulator_description/meshes/khi_rs/RS005L_J0.STL" />
            </geometry>
            <material name="White" />
            <origin rpy="0 0 0" xyz="0 0 0" />
        </collision>
        <inertial>
            <mass value="5.91" />
            <inertia ixx="1.0" ixy="0.0" ixz="0.0" iyy="1.0" iyz="0.0" izz="1.0" />
            <origin xyz="0 0 0" rpy="0 0 0" />
        </inertial>
    </link>
    <!-- Link 1 -->
    <joint name="joint1" type="revolute">
        <axis rpy="0 0 0" xyz="0 0 -1" />
        <limit effort="1000.0" lower="-3.141592653589793" upper="3.141592653589793" velocity="5.235987755982989" />
        <origin rpy="0 0 0" xyz="0 0 0.295" />
        <parent link="base_link" />
        <child link="link1" />
        <dynamics damping="0.0" friction="0.0" />
    </joint>
    <link name="link1">
        <visual>
            <geometry>
                <mesh filename="package://mobile_manipulator_description/meshes/khi_rs/RS005L_J1.STL" />
            </geometry>
            <material name="White" />
            <origin rpy="0 0 0" xyz="0 0 0" />
        </visual>
        <collision>
            <geometry>
                <mesh filename="package://mobile_manipulator_description/meshes/khi_rs/RS005L_J1.STL" />
            </geometry>
            <material name="White" />
            <origin rpy="0 0 0" xyz="0 0 0" />
        </collision>
        <inertial>
            <mass value="10.395" />
            <inertia ixx="1.0" ixy="0.0" ixz="0.0" iyy="1.0" iyz="0.0" izz="1.0" />
            <origin xyz="0 0 0" rpy="0 0 0" />
        </inertial>
    </link>
    <!-- Link 2 -->
    <joint name="joint2" type="revolute">
        <axis rpy="0 0 0" xyz="0 0 1" />
        <limit effort="1000.0" lower="-1.3962634015954636" upper="2.356194490192345" velocity="5.235987755982989" />
        <origin rpy="0 -1.5707963267948966 0" xyz="0 0.105 0" />
        <parent link="link1" />
        <child link="link2" />
        <dynamics damping="0.0" friction="0.0" />
    </joint>
    <link name="link2">
        <visual>
            <geometry>
                <mesh filename="package://mobile_manipulator_description/meshes/khi_rs/RS005L_J2.STL" />
            </geometry>
            <material name="White" />
            <origin rpy="0 0 0" xyz="0 0 0" />
        </visual>
        <collision>
            <geometry>
                <mesh filename="package://mobile_manipulator_description/meshes/khi_rs/RS005L_J2.STL" />
            </geometry>
            <material name="White" />
            <origin rpy="0 0 0" xyz="0 0 0" />
        </collision>
        <inertial>
            <mass value="8.788" />
            <inertia ixx="1.0" ixy="0.0" ixz="0.0" iyy="1.0" iyz="0.0" izz="1.0" />
            <origin xyz="0 0 0" rpy="0 0 0" />
        </inertial>
    </link>
    <!-- Link 3 -->
    <joint name="joint3" type="revolute">
        <axis rpy="0 0 0" xyz="0 0 -1" />
        <limit effort="1000.0" lower="-3.001966313430247" upper="2.059488517353309" velocity="5.235987755982989" />
        <origin rpy="0 0 0" xyz="0.38 0 0" />
        <parent link="link2" />
        <child link="link3" />
        <dynamics damping="0.0" friction="0.0" />
    </joint>
    <link name="link3">
        <visual>
            <geometry>
                <mesh filename="package://mobile_manipulator_description/meshes/khi_rs/RS005L_J3.STL" />
            </geometry>
            <material name="White" />
            <origin rpy="0 0 0" xyz="0 0 0" />
        </visual>
        <collision>
            <geometry>
                <mesh filename="package://mobile_manipulator_description/meshes/khi_rs/RS005L_J3.STL" />
            </geometry>
            <material name="White" />
            <origin rpy="0 0 0" xyz="0 0 0" />
        </collision>
        <inertial>
            <mass value="7.575" />
            <inertia ixx="1.0" ixy="0.0" ixz="0.0" iyy="1.0" iyz="0.0" izz="1.0" />
            <origin xyz="0 0 0" rpy="0 0 0" />
        </inertial>
    </link>
    <!-- Link 4 -->
    <joint name="joint4" type="revolute">
        <axis rpy="0 0 0" xyz="0 0 1" />
        <limit effort="1000.0" lower="-6.283185307179586" upper="6.283185307179586" velocity="8.028514559173916" />
        <origin rpy="0 1.5707963267948966 0" xyz="0.15 -0.08 0" />
        <parent link="link3" />
        <child link="link4" />
        <dynamics damping="0.0" friction="0.0" />
    </joint>
    <link name="link4">
        <visual>
            <geometry>
                <mesh filename="package://mobile_manipulator_description/meshes/khi_rs/RS005L_J4.STL" />
            </geometry>
            <material name="White" />
            <origin rpy="0 0 0" xyz="0 0 0" />
        </visual>
        <collision>
            <geometry>
                <mesh filename="package://mobile_manipulator_description/meshes/khi_rs/RS005L_J4.STL" />
            </geometry>
            <material name="White" />
            <origin rpy="0 0 0" xyz="0 0 0" />
        </collision>
        <inertial>
            <mass value="2.679" />
            <inertia ixx="1.0" ixy="0.0" ixz="0.0" iyy="1.0" iyz="0.0" izz="1.0" />
            <origin xyz="0 0 0" rpy="0 0 0" />
        </inertial>
    </link>
    <!-- Link 5 -->
    <joint name="joint5" type="revolute">
        <axis rpy="0 0 0" xyz="0 0 -1" />
        <limit effort="1000.0" lower="-2.530727415391778" upper="2.530727415391778" velocity="8.028514559173916" />
        <origin rpy="0 -1.5707963267948966 0" xyz="0 0 0.26" />
        <parent link="link4" />
        <child link="link5" />
        <dynamics damping="0.0" friction="0.0" />
    </joint>
    <link name="link5">
        <visual>
            <geometry>
                <mesh filename="package://mobile_manipulator_description/meshes/khi_rs/RS005L_J5.STL" />
            </geometry>
            <material name="White" />
            <origin rpy="0 0 0" xyz="0 0 0" />
        </visual>
        <collision>
            <geometry>
                <mesh filename="package://mobile_manipulator_description/meshes/khi_rs/RS005L_J5.STL" />
            </geometry>
            <material name="White" />
            <origin rpy="0 0 0" xyz="0 0 0" />
        </collision>
        <inertial>
            <mass value="1.028" />
            <inertia ixx="1.0" ixy="0.0" ixz="0.0" iyy="1.0" iyz="0.0" izz="1.0" />
            <origin xyz="0 0 0" rpy="0 0 0" />
        </inertial>
    </link>
    <!-- Link 6 -->
    <joint name="joint6" type="revolute">
        <axis rpy="0 0 0" xyz="0 0 1" />
        <limit effort="1000.0" lower="-6.283185307179586" upper="6.283185307179586" velocity="12.915436464758038" />
        <origin rpy="0 1.5707963267948966 0" xyz="0.078 0 0" />
        <parent link="link5" />
        <child link="link6" />
        <dynamics damping="0.0" friction="0.0" />
    </joint>
    <link name="link6">
        <visual>
            <geometry>
                <mesh filename="package://mobile_manipulator_description/meshes/khi_rs/RS005L_J6.STL" />
            </geometry>
            <material name="Black" />
            <origin rpy="0 0 0" xyz="0 0 0" />
        </visual>
        <collision>
            <geometry>
                <mesh filename="package://mobile_manipulator_description/meshes/khi_rs/RS005L_J6.STL" />
            </geometry>
            <material name="Black" />
            <origin rpy="0 0 0" xyz="0 0 0" />
        </collision>
        <inertial>
            <mass value="0.625" />
            <inertia ixx="1.0" ixy="0.0" ixz="0.0" iyy="1.0" iyz="0.0" izz="1.0" />
            <origin xyz="0 0 0" rpy="0 0 0" />
        </inertial>
    </link>
    <!-- Link 6 -->
    <joint name="joint7" type="fixed">
        <axis rpy="0 0 0" xyz="0 0 1" />
        <origin rpy="1.570796 -1.570796 0" xyz="0.04 -0.035 0.22" />
        <parent link="link6" />
        <child link="link7" />
    </joint>
    <link name="link7">
        <visual>
            <geometry>
                <mesh filename="package://mobile_manipulator_description/meshes/khi_rs/Montaj.stl" scale="0.001 0.001 0.001" />
            </geometry>
            <material name="Black" />
            <origin rpy="0 -1.570796 1.570796" xyz="0 0 0" />
        </visual>
        <collision>
            <geometry>
                <mesh filename="package://mobile_manipulator_description/meshes/khi_rs/Montaj.stl" scale="0.001 0.001 0.001" />
            </geometry>
            <material name="Black" />
            <origin rpy="0 -1.570796 1.570796" xyz="0 0 0" />
        </collision>
        <inertial>
            <mass value="0.2" />
            <inertia ixx="1.0" ixy="0.0" ixz="0.0" iyy="1.0" iyz="0.0" izz="1.0" />
            <origin xyz="0 0 0" rpy="0 0 0" />
        </inertial>
    </link>
    <link name="camera_link" />
    <joint name="camera_joint" type="fixed">
        <origin rpy="0 0 0" xyz="-0.04 0.0525 -0.021" />
        <parent link="link7" />
        <child link="camera_link" />
    </joint>
    <joint name="camera_rgb_joint" type="fixed">
        <origin rpy="0 0 0" xyz="0 0 0" />
        <parent link="camera_link" />
        <child link="camera_rgb_frame" />
    </joint>
    <link name="camera_rgb_frame" />
    <joint name="camera_rgb_optic_joint" type="fixed">
        <origin rpy="0 0 0" xyz="0 0 0" />
        <parent link="camera_rgb_frame" />
        <child link="camera_rgb_optic_frame" />
    </joint>
    <link name="camera_rgb_optic_frame" />
    <gazebo reference="camera_link">
        <sensor name="Realsense_Camera_Depth" type="depth">
            <always_on>true</always_on>
            <update_rate>30.0</update_rate>
            <camera>
                <horizontal_fov>1.22</horizontal_fov>
                <image>
                    <width>512</width>
                    <height>424</height>
                    <format>R8G8B8</format>
                </image>
                <clip>
                    <near>0.01</near>
                    <far>16</far>
                </clip>
            </camera>
            <plugin filename="libgazebo_ros_openni_kinect.so" name="depth_camera_plugin">
                <visualize>true</visualize>
                <alwaysOn>true</alwaysOn>
                <updateRate>30.0</updateRate>
                <cameraName>camera</cameraName>
                <imageTopicName>image_raw</imageTopicName>
                <cameraInfoTopicName>camera_info</cameraInfoTopicName>
                <depthImageTopicName>depth_image_raw</depthImageTopicName>
                <depthImageCameraInfoTopicName>depth_camera_info</depthImageCameraInfoTopicName>
                <pointCloudTopicName>points</pointCloudTopicName>
                <frameName>camera_rgb_optic_frame</frameName>
                <pointCloudCutoff>0.0</pointCloudCutoff>
                <distortionK1>0.00000001</distortionK1>
                <distortionK2>0.00000001</distortionK2>
                <distortionK3>0.00000001</distortionK3>
                <distortionT1>0.00000001</distortionT1>
                <distortionT2>0.00000001</distortionT2>
                <CxPrime>0</CxPrime>
                <Cx>0</Cx>
                <Cy>0</Cy>
                <focalLength>0</focalLength>
                <hackBaseline>0</hackBaseline>
            </plugin>
        </sensor>
    </gazebo>
    <link name="ota_base_link">
        <origin rpy=" 0 0 0" xyz="0 0 0" />
        <visual>
            <origin rpy=" 0 0 0" xyz="0 0 -0.1625" />
            <geometry>
                <mesh filename="package://mobile_manipulator_description/meshes/ota/OTA-v0.7.stl" scale="0.001 0.001 0.001" />
            </geometry>
        </visual>
        <collision>
            <origin rpy=" 0 0 0" xyz="0 0 -0.0" />
            <geometry>
                <box size="1.02605 0.728 0.25" />
            </geometry>
        </collision>
        <inertial>
            <mass value="50.0" />
            <origin xyz="0 0 0" rpy="0 0 0" />
            <inertia ixx="2.58326563336" ixy="0.0" ixz="0.0" iyy="4.761575605785662" iyz="0.0" izz="6.594841539145662" />
        </inertial>
    </link>
    <gazebo reference="ota_base_link">
        <material value="Gazebo/Orange" />
    </gazebo>
    <link name="manipulator_base_link">
        <origin rpy=" 0 0 0" xyz="0 0 0" />
        <visual>
            <origin rpy=" 0 0 0" xyz="0 0 -0.0" />
            <geometry>
                <box size="0.187945 0.190701 0.103" />
            </geometry>
        </visual>
        <collision>
            <origin rpy=" 0 0 0" xyz="0 0 -0.0" />
            <geometry>
                <box size="0.187945 0.190701 0.103" />
            </geometry>
        </collision>
        <inertial>
            <mass value="5.0" />
            <origin xyz="0 0 0" rpy="0 0 0" />
            <inertia ixx="0.01957327192110477" ixy="0.0" ixz="0.0" iyy="0.01913846027169616" iyz="0.0" izz="0.029870902395800928" />
        </inertial>
    </link>
    <gazebo reference="manipulator_base_link">
        <material value="Gazebo/Orange" />
    </gazebo>
    <joint name="base2manipulatorbase" type="fixed">
        <parent link="ota_base_link" />
        <child link="manipulator_base_link" />
        <origin rpy="0 0 0" xyz="0.001 -0.26 0.212" />
    </joint>
    <link name="camera1_link">
        <visual>
            <origin rpy="1.57 0 1.57" xyz="-0.03 0 0" />
            <geometry>
                <mesh filename="package://mobile_manipulator_description/meshes/camera.stl" scale="0.001 0.001 0.001" />
            </geometry>
        </visual>
    </link>
    <joint name="camera1_joint" type="fixed">
        <origin rpy="0 0 -0.785398163" xyz="0.1 -0.1 0.05" />
        <parent link="manipulator_base_link" />
        <child link="camera1_link" />
    </joint>
    <joint name="camera1_rgb_joint" type="fixed">
        <origin rpy="-1.570796 0 -1.570796" xyz="0 0 0" />
        <parent link="camera1_link" />
        <child link="camera1_rgb_frame" />
    </joint>
    <link name="camera1_rgb_frame" />
    <joint name="camera1_rgb_optic_joint" type="fixed">
        <origin rpy="0 0 0" xyz="0 0 0" />
        <parent link="camera1_rgb_frame" />
        <child link="camera1_rgb_optic_frame" />
    </joint>
    <link name="camera1_rgb_optic_frame" />
    <gazebo reference="camera1_link">
        <sensor name="Realsense_Camera_Depth" type="depth">
            <always_on>true</always_on>
            <update_rate>10.0</update_rate>
            <camera>
                <horizontal_fov>1.3962634</horizontal_fov>
                <image>
                    <width>640</width>
                    <height>480</height>
                    <format>R8G8B8</format>
                </image>
                <clip>
                    <near>0.01</near>
                    <far>5</far>
                </clip>
            </camera>
            <plugin filename="libgazebo_ros_openni_kinect.so" name="depth_camera_plugin">
                <alwaysOn>true</alwaysOn>
                <updateRate>10.0</updateRate>
                <cameraName>camera1</cameraName>
                <imageTopicName>image_raw</imageTopicName>
                <cameraInfoTopicName>camera_info</cameraInfoTopicName>
                <depthImageTopicName>depth_image_raw</depthImageTopicName>
                <depthImageCameraInfoTopicName>depth_camera_info</depthImageCameraInfoTopicName>
                <pointCloudTopicName>points</pointCloudTopicName>
                <frameName>camera1_rgb_optic_frame</frameName>
                <pointCloudCutoff>0.0</pointCloudCutoff>
                <distortionK1>0.00000001</distortionK1>
                <distortionK2>0.00000001</distortionK2>
                <distortionK3>0.00000001</distortionK3>
                <distortionT1>0.00000001</distortionT1>
                <distortionT2>0.00000001</distortionT2>
                <CxPrime>0</CxPrime>
                <Cx>0</Cx>
                <Cy>0</Cy>
                <focalLength>0</focalLength>
                <hackBaseline>0</hackBaseline>
            </plugin>
        </sensor>
    </gazebo>
    <link name="camera2_link">
        <visual>
            <origin rpy="1.57 0 1.57" xyz="-0.03 0 0" />
            <geometry>
                <mesh filename="package://mobile_manipulator_description/meshes/camera.stl" scale="0.001 0.001 0.001" />
            </geometry>
        </visual>
    </link>
    <joint name="camera2_joint" type="fixed">
        <origin rpy="0 0 -2.35619449" xyz="-0.1 -0.1 0.05" />
        <parent link="manipulator_base_link" />
        <child link="camera2_link" />
    </joint>
    <joint name="camera2_rgb_joint" type="fixed">
        <origin rpy="-1.570796 0 -1.570796" xyz="0 0 0" />
        <parent link="camera2_link" />
        <child link="camera2_rgb_frame" />
    </joint>
    <link name="camera2_rgb_frame" />
    <joint name="camera2_rgb_optic_joint" type="fixed">
        <origin rpy="0 0 0" xyz="0 0 0" />
        <parent link="camera2_rgb_frame" />
        <child link="camera2_rgb_optic_frame" />
    </joint>
    <link name="camera2_rgb_optic_frame" />
    <gazebo reference="camera2_link">
        <sensor name="Realsense_Camera_Depth" type="depth">
            <always_on>true</always_on>
            <update_rate>10.0</update_rate>
            <camera>
                <horizontal_fov>1.3962634</horizontal_fov>
                <image>
                    <width>640</width>
                    <height>480</height>
                    <format>R8G8B8</format>
                </image>
                <clip>
                    <near>0.01</near>
                    <far>5</far>
                </clip>
            </camera>
            <plugin filename="libgazebo_ros_openni_kinect.so" name="depth_camera_plugin">
                <pose>0 0 0 1.570796 -0 0</pose>
                <alwaysOn>true</alwaysOn>
                <updateRate>10.0</updateRate>
                <cameraName>camera2</cameraName>
                <imageTopicName>image_raw</imageTopicName>
                <cameraInfoTopicName>camera_info</cameraInfoTopicName>
                <depthImageTopicName>depth_image_raw</depthImageTopicName>
                <depthImageCameraInfoTopicName>depth_camera_info</depthImageCameraInfoTopicName>
                <pointCloudTopicName>points</pointCloudTopicName>
                <frameName>camera2_rgb_optic_frame</frameName>
                <pointCloudCutoff>0.0</pointCloudCutoff>
                <distortionK1>0.00000001</distortionK1>
                <distortionK2>0.00000001</distortionK2>
                <distortionK3>0.00000001</distortionK3>
                <distortionT1>0.00000001</distortionT1>
                <distortionT2>0.00000001</distortionT2>
                <CxPrime>0</CxPrime>
                <Cx>0</Cx>
                <Cy>0</Cy>
                <focalLength>0</focalLength>
                <hackBaseline>0</hackBaseline>
            </plugin>
        </sensor>
    </gazebo>
    <link name="ota_ir_link">
        <inertial>
            <origin rpy="0 0 0" xyz="0 0 0" />
            <mass value="0.001" />
            <inertia ixx="0.001666" ixy="0" ixz="0" iyy="0.001666" iyz="0" izz="0.001666" />
        </inertial>
        <visual>
            <origin rpy="0 0 0" xyz="0 0 0" />
            <geometry>
                <mesh filename="package://mobile_manipulator_description/meshes/ota/FotoelektrikSensor.stl" scale="0.0015 0.0015 0.0015" />
            </geometry>
        </visual>
        <collision>
            <origin rpy="0 0 0" xyz="0 0 0" />
            <geometry>
                <box size="0.01 0.01 0.01" />
            </geometry>
        </collision>
    </link>
    <joint name="ota_ir_joint" type="fixed">
        <origin rpy="0 0 0" xyz="0.503 0.0 0.03" />
        <parent link="ota_base_link" />
        <child link="ota_ir_link" />
    </joint>
    <gazebo reference="ota_ir_link">
        <sensor name="ota_ir" type="ray">
            <pose>0 0 0 0 0 0</pose>
            <ray>
                <scan>
                    <horizontal>
                        <samples>320</samples>
                        <resolution>1</resolution>
                        <min_angle>-0.001</min_angle>
                        <max_angle>0.001</max_angle>
                    </horizontal>
                </scan>
                <range>
                    <min>0.2</min>
                    <max>8.0</max>
                    <resolution>0.01</resolution>
                </range>
            </ray>
            <plugin filename="libgazebo_ros_range.so" name="gazebo_ros_range">
                <topicName>ota_ir</topicName>
                <frameName>ota_ir_link</frameName>
                <frameId>ota_ir_link</frameId>
                <radiation>ultrasound</radiation>
                <fov>0.7</fov>
                <gaussianNoise>0</gaussianNoise>
            </plugin>
            <always_on>1</always_on>
            <update_rate>4</update_rate>
            <visualize>true</visualize>
        </sensor>
    </gazebo>
    <link name="wheel_left_link">
        <visual>
            <origin rpy=" 0 0 1.570796" xyz="0 0 0" />
            <geometry>
                <mesh filename="package://mobile_manipulator_description/meshes/ota/AnaTeker.stl" scale="0.001 0.001 0.001" />
            </geometry>
        </visual>
        <collision>
            <origin rpy="0 1.570796 1.570796" xyz="0 0 0" />
            <geometry>
                <cylinder length="0.02" radius="0.102" />
            </geometry>
        </collision>
        <inertial>
            <mass value="5" />
            <origin xyz="0 0 0" rpy="0 0 0" />
            <inertia ixx="0.013171661397999997" ixy="0.0" ixz="0.0" iyy="0.013171661397999997" iyz="0.0" izz="0.02601" />
        </inertial>
    </link>
    <joint name="wheel_left_base" type="continuous">
        <origin rpy="0 0 0" xyz="0 -0.30 -0.06" />
        <parent link="ota_base_link" />
        <child link="wheel_left_link" />
        <axis xyz="0 1 0" />
    </joint>
    <gazebo reference="wheel_left_link">
        <material value="Gazebo/Green" />
    </gazebo>
    <link name="wheel_right_link">
        <visual>
            <origin rpy=" 0 0 1.570796" xyz="0 0 0" />
            <geometry>
                <mesh filename="package://mobile_manipulator_description/meshes/ota/AnaTeker.stl" scale="0.001 0.001 0.001" />
            </geometry>
        </visual>
        <collision>
            <origin rpy="0 1.570796 1.570796" xyz="0 0 0" />
            <geometry>
                <cylinder length="0.02" radius="0.102" />
            </geometry>
        </collision>
        <inertial>
            <mass value="5" />
            <origin xyz="0 0 0" rpy="0 0 0" />
            <inertia ixx="0.013171661397999997" ixy="0.0" ixz="0.0" iyy="0.013171661397999997" iyz="0.0" izz="0.02601" />
        </inertial>
    </link>
    <joint name="wheel_right_base" type="continuous">
        <origin rpy="0 0 0" xyz="0 0.30 -0.06" />
        <parent link="ota_base_link" />
        <child link="wheel_right_link" />
        <axis xyz="0 1 0" />
    </joint>
    <gazebo reference="wheel_right_link">
        <material value="Gazebo/Green" />
    </gazebo>
    <link name="caster_front_right_link">
        <visual>
            <origin rpy=" 0 0 0" xyz="0 0 0" />
            <geometry>
                <mesh filename="package://mobile_manipulator_description/meshes/ota/SarhosTeker.stl" scale="0.001 0.0008 0.001" />
            </geometry>
        </visual>
        <collision>
            <origin rpy="0 0 0" xyz="0 0 0" />
            <geometry>
                <cylinder length="0.05" radius="0.005" />
            </geometry>
        </collision>
        <inertial>
            <mass value="1" />
            <origin xyz="0 0 0" rpy="0 0 0" />
            <inertia ixx="0.0004145831675000001" ixy="0.0" ixz="0.0" iyy="0.0004145831675000001" iyz="0.0" izz="1.25e-05" />
        </inertial>
    </link>
    <joint name="caster_front_right_joint" type="fixed">
        <origin rpy="0 0 0" xyz="0.37 -0.22 -0.048" />
        <axis xyz="0 0 1" />
        <parent link="ota_base_link" />
        <child link="caster_front_right_link" />
    </joint>
    <gazebo reference="caster_front_right_link">
        <material value="Gazebo/Gray" />
    </gazebo>
    <link name="caster_wheel_front_right_link">
        <collision>
            <origin rpy="0 1.570796 1.570796" xyz="0 0 0" />
            <geometry>
                <cylinder length="0.02" radius="0.042" />
            </geometry>
        </collision>
        <inertial>
            <mass value="0.1" />
            <origin xyz="0 0 0" rpy="0 0 0" />
            <inertia ixx="4.7433314360000004e-05" ixy="0.0" ixz="0.0" iyy="4.7433314360000004e-05" iyz="0.0" izz="8.820000000000002e-05" />
        </inertial>
    </link>
    <joint name="caster_front_right_wheel_joint" type="fixed">
        <axis xyz="0 1 0" />
        <origin rpy="0 0 0" xyz="-0.04 0 -0.07" />
        <parent link="caster_front_right_link" />
        <child link="caster_wheel_front_right_link" />
    </joint>
    <link name="caster_front_left_link">
        <visual>
            <origin rpy=" 0 0 0" xyz="0 0 0" />
            <geometry>
                <mesh filename="package://mobile_manipulator_description/meshes/ota/SarhosTeker.stl" scale="0.001 0.0008 0.001" />
            </geometry>
        </visual>
        <collision>
            <origin rpy="0 0 0" xyz="0 0 0" />
            <geometry>
                <cylinder length="0.05" radius="0.005" />
            </geometry>
        </collision>
        <inertial>
            <mass value="1" />
            <origin xyz="0 0 0" rpy="0 0 0" />
            <inertia ixx="0.0004145831675000001" ixy="0.0" ixz="0.0" iyy="0.0004145831675000001" iyz="0.0" izz="1.25e-05" />
        </inertial>
    </link>
    <joint name="caster_front_left_joint" type="fixed">
        <origin rpy="0 0 0" xyz="0.37 0.22 -0.048" />
        <axis xyz="0 0 1" />
        <parent link="ota_base_link" />
        <child link="caster_front_left_link" />
    </joint>
    <gazebo reference="caster_front_left_link">
        <material value="Gazebo/Gray" />
    </gazebo>
    <link name="caster_wheel_front_left_link">
        <collision>
            <origin rpy="0 1.570796 1.570796" xyz="0 0 0" />
            <geometry>
                <cylinder length="0.02" radius="0.042" />
            </geometry>
        </collision>
        <inertial>
            <mass value="0.1" />
            <origin xyz="0 0 0" rpy="0 0 0" />
            <inertia ixx="4.7433314360000004e-05" ixy="0.0" ixz="0.0" iyy="4.7433314360000004e-05" iyz="0.0" izz="8.820000000000002e-05" />
        </inertial>
    </link>
    <joint name="caster_front_left_wheel_joint" type="fixed">
        <axis xyz="0 1 0" />
        <origin rpy="0 0 0" xyz="-0.04 0 -0.07" />
        <parent link="caster_front_left_link" />
        <child link="caster_wheel_front_left_link" />
    </joint>
    <link name="caster_back_right_link">
        <visual>
            <origin rpy=" 0 0 0" xyz="0 0 0" />
            <geometry>
                <mesh filename="package://mobile_manipulator_description/meshes/ota/SarhosTeker.stl" scale="0.001 0.0008 0.001" />
            </geometry>
        </visual>
        <collision>
            <origin rpy="0 0 0" xyz="0 0 0" />
            <geometry>
                <cylinder length="0.05" radius="0.005" />
            </geometry>
        </collision>
        <inertial>
            <mass value="1" />
            <origin xyz="0 0 0" rpy="0 0 0" />
            <inertia ixx="0.0004145831675000001" ixy="0.0" ixz="0.0" iyy="0.0004145831675000001" iyz="0.0" izz="1.25e-05" />
        </inertial>
    </link>
    <joint name="caster_back_right_joint" type="fixed">
        <origin rpy="0 0 0" xyz="-0.37 -0.22 -0.048" />
        <axis xyz="0 0 1" />
        <parent link="ota_base_link" />
        <child link="caster_back_right_link" />
    </joint>
    <gazebo reference="caster_back_right_link">
        <material value="Gazebo/Gray" />
    </gazebo>
    <link name="caster_wheel_back_right_link">
        <collision>
            <origin rpy="0 1.570796 1.570796" xyz="0 0 0" />
            <geometry>
                <cylinder length="0.02" radius="0.042" />
            </geometry>
        </collision>
        <inertial>
            <mass value="0.1" />
            <origin xyz="0 0 0" rpy="0 0 0" />
            <inertia ixx="4.7433314360000004e-05" ixy="0.0" ixz="0.0" iyy="4.7433314360000004e-05" iyz="0.0" izz="8.820000000000002e-05" />
        </inertial>
    </link>
    <joint name="caster_back_right_wheel_joint" type="fixed">
        <axis xyz="0 1 0" />
        <origin rpy="0 0 0" xyz="-0.04 0 -0.07" />
        <parent link="caster_back_right_link" />
        <child link="caster_wheel_back_right_link" />
    </joint>
    <link name="caster_back_left_link">
        <visual>
            <origin rpy=" 0 0 0" xyz="0 0 0" />
            <geometry>
                <mesh filename="package://mobile_manipulator_description/meshes/ota/SarhosTeker.stl" scale="0.001 0.0008 0.001" />
            </geometry>
        </visual>
        <collision>
            <origin rpy="0 0 0" xyz="0 0 0" />
            <geometry>
                <cylinder length="0.05" radius="0.005" />
            </geometry>
        </collision>
        <inertial>
            <mass value="1" />
            <origin xyz="0 0 0" rpy="0 0 0" />
            <inertia ixx="0.0004145831675000001" ixy="0.0" ixz="0.0" iyy="0.0004145831675000001" iyz="0.0" izz="1.25e-05" />
        </inertial>
    </link>
    <joint name="caster_back_left_joint" type="fixed">
        <origin rpy="0 0 0" xyz="-0.37 0.22 -0.048" />
        <axis xyz="0 0 1" />
        <parent link="ota_base_link" />
        <child link="caster_back_left_link" />
    </joint>
    <gazebo reference="caster_back_left_link">
        <material value="Gazebo/Gray" />
    </gazebo>
    <link name="caster_wheel_back_left_link">
        <collision>
            <origin rpy="0 1.570796 1.570796" xyz="0 0 0" />
            <geometry>
                <cylinder length="0.02" radius="0.042" />
            </geometry>
        </collision>
        <inertial>
            <mass value="0.1" />
            <origin xyz="0 0 0" rpy="0 0 0" />
            <inertia ixx="4.7433314360000004e-05" ixy="0.0" ixz="0.0" iyy="4.7433314360000004e-05" iyz="0.0" izz="8.820000000000002e-05" />
        </inertial>
    </link>
    <joint name="caster_back_left_wheel_joint" type="fixed">
        <axis xyz="0 1 0" />
        <origin rpy="0 0 0" xyz="-0.04 0 -0.07" />
        <parent link="caster_back_left_link" />
        <child link="caster_wheel_back_left_link" />
    </joint>
    <gazebo>
        <plugin filename="libgazebo_ros_diff_drive.so" name="differential_drive_controller">
            <robotNamespace>/</robotNamespace>
            <publishOdomTF>true</publishOdomTF>
            <publishWheelJointState>true</publishWheelJointState>
            <alwaysOn>true</alwaysOn>
            <leftJoint>wheel_right_base</leftJoint>
            <rightJoint>wheel_left_base</rightJoint>
            <wheelSeparation>0.60</wheelSeparation>
            <wheelDiameter>0.20</wheelDiameter>
            <wheelTorque>20</wheelTorque>
            <wheelAcceleration>1.8</wheelAcceleration>
            <commandTopic>cmd_vel</commandTopic>
            <odometryTopic>sim_odom</odometryTopic>
            <odometryFrame>sim_odom</odometryFrame>
            <odometrySource>world</odometrySource>
            <robotBaseFrame>ota_base_link</robotBaseFrame>
            <legacyMode>true</legacyMode>
            <publishTf>false</publishTf>
            <updateRate>50.0</updateRate>
        </plugin>
    </gazebo>
    <gazebo>
        <plugin filename="libgazebo_ros_joint_state_publisher.so" name="joint_state_publisher">
            <robotNamespace />
            <!--            <jointName>caster_front_left_joint,caster_front_right_joint,caster_back_left_joint,caster_back_right_joint,caster_front_left_wheel_joint,caster_front_right_wheel_joint,caster_back_left_wheel_joint,caster_back_right_wheel_joint</jointName>-->
            <joint_name>caster_front_left_joint</joint_name>
            <joint_name>caster_front_right_joint</joint_name>
            <joint_name>caster_back_left_joint</joint_name>
            <joint_name>caster_back_right_joint</joint_name>
            <joint_name>caster_front_left_wheel_joint</joint_name>
            <joint_name>caster_front_right_wheel_joint</joint_name>
            <joint_name>caster_back_left_wheel_joint</joint_name>
            <joint_name>caster_back_right_wheel_joint</joint_name>
            <updateRate>50.0</updateRate>
            <alwaysOn>true</alwaysOn>
        </plugin>
    </gazebo>
    <!-- Fix rs005l to ota -->
    <joint name="world2base" type="fixed">
        <parent link="manipulator_base_link" />
        <child link="base_link" />
        <origin rpy="0 0 3.141593" xyz="0 -0.0 0.051" />
    </joint>
    <transmission name="trans_wheel_left_base">
        <type>transmission_interface/SimpleTransmission</type>
        <joint name="wheel_left_base">
            <hardwareInterface>hardware_interface/EffortJointInterface</hardwareInterface>
        </joint>
        <actuator name="wheel_left_base_motor">
            <hardwareInterface>hardware_interface/EffortJointInterface</hardwareInterface>
            <mechanicalReduction>1</mechanicalReduction>
        </actuator>
    </transmission>
    <transmission name="trans_wheel_right_base">
        <type>transmission_interface/SimpleTransmission</type>
        <joint name="wheel_right_base">
            <hardwareInterface>hardware_interface/EffortJointInterface</hardwareInterface>
        </joint>
        <actuator name="wheel_right_base_motor">
            <hardwareInterface>hardware_interface/EffortJointInterface</hardwareInterface>
            <mechanicalReduction>1</mechanicalReduction>
        </actuator>
    </transmission>
</robot>

